<robot name="piano_bot">
	<!--底盘--><!--这是注释-->
	<link name ="underpan">
		<visual>
			<geometry><box size="0.5 0.4 0.1"/></geometry>
			<!--参数都是以米为单位-->	
		</visual>
		<collision>
			<geometry><box size="0.5 0.4 0.1"/></geometry>	
			<!--基本状态下ros的x轴朝前，y轴朝左，z轴朝上-->
		</collision>
	</link>
	
	<!--杆子-->
	<link name="spine">
		<visual>
			<origin rpy="0 0 0"xyz="0 0 0.6" />
			<geometry><box size="0.1 0.2 1.2" /></geometry>
		</visual>	
		<collision>
			<origin rpy="0 0 0"xyz="0 0 0.6"/>
			<geometry><box size="0.1 0.2 1.2"/></geometry>
		</collision>
	</link>
	
	<!--四个轮子-->
	<link name="wheel_left_front"><!--左前轮-->
		<visual>
			<origin rpy="0 0 0"xyz="0 0 0" />
			<geometry><cylinder radius="0.1"length="0.05" /></geometry>
		</visual>	
		<collision>
			<origin rpy="0 0 0"xyz="0 0 0" />
			<geometry><cylinder radius="0.1"length="0.05" /></geometry>
		</collision>
	</link>	
	<link name="wheel_left_back"><!--左后轮-->
		<visual>
			<origin rpy="0 0 0"xyz="0 0 0" />
			<geometry><cylinder radius="0.1"length="0.05" /></geometry>
		</visual>	
		<collision>
			<origin rpy="0 0 0"xyz="0 0 0" />
			<geometry><cylinder radius="0.1"length="0.05" /></geometry>
		</collision>
	</link>	
	<link name="wheel_right_front"><!--右前轮-->
		<visual>
			<origin rpy="0 0 0"xyz="0 0 0" />
			<geometry><cylinder radius="0.1"length="0.05" /></geometry>
		</visual>	
		<collision>
			<origin rpy="0 0 0"xyz="0 0 0" />
			<geometry><cylinder radius="0.1"length="0.05" /></geometry>
		</collision>
	</link>	
	<link name="wheel_right_back"><!--右后轮-->
		<visual>
			<origin rpy="0 0 0"xyz="0 0 0" />
			<geometry><cylinder radius="0.1"length="0.05" /></geometry>
		</visual>	
		<collision>
			<origin rpy="0 0 0"xyz="0 0 0" />
			<geometry><cylinder radius="0.1"length="0.05" /></geometry>
		</collision>
	</link>	


	<!--连接底座和杆子-->
	<joint name="base joint" type="fixed">
		<parent link="underpan"/>
		<child link="spine"/>
		<original rpy="0 0 0"xyz="0.2 0 0.05"/>
	</joint>
	
	<!--连接四个轮子-->
	<!--左前-->
	<joint name="wheel_joint1" type="planar">
		<parent link="underpan"/>
		<child link="wheel_left_front"/>
		<original rpy="1.57 0 0"xyz="0.2 0.225 0"/>
		<!--rpy即欧拉角是用弧度表示，90度应该是1.57-->
		<axis xyz="0 0 1" />
	</joint>
	<!--右前-->
	<joint name="wheel_joint2" type="planar">
		<parent link="underpan"/>
		<child link="wheel_right_front"/>
		<original rpy="1.57 0 0"xyz="0.2 -0.225 0"/>
		<axis xyz="0 0 1" />
	</joint>
	<!--左后-->
	<joint name="wheel_joint3" type="planar">
		<parent link="underpan"/>
		<child link="wheel_left_back"/>
		<original rpy="1.57 0 0"xyz="-0.2 0.225 0"/>
		<axis xyz="0 0 1" />
	</joint>
	<!--右后-->
	<joint name="wheel_joint4" type="planar">
		<parent link="underpan"/>
		<child link="wheel_right_back"/>
		<original rpy="1.57 0 0"xyz="-0.2 -0.225 0"/>
		<axis xyz="0 0 1" />
	</joint>
	
</robot>

